Workbook

Sheet SUMMARY
B2: Row Labels | C2: Count of REMARKS | D2: Mafaz Comments
B3: Bartec (SKF) | C3: 1 | D3: System Errors
B4: Sample | C4: 8 | D4: Division will be Responsible
B5: customer will Retun | C5: 5 | D5: Division will be Responsible
B6: Description is not matching from ERP | C6: 1 | D6: System Errors
B7: ISR not Available | C7: 2 | D7: Division will be Responsible
B8: MISSING | C8: 17 | D8: Logistic Re- checking
B9: Pending to close | C9: 9 | D9: Logistic will be Responsible
B10: Return to Supplier | C10: 1 | D10: Division will be Responsible
B11: RMA is Pending | C11: 2 | D11: Logistic Re- checking
B12: Stock Matching | C12: 184 | D12: Logistic will be Responsible
B13: Grand Total | C13: 230

Sheet Counting Sheet
A2: No | B2: ITEM_CODE | C2: ITEM_DESCRIPTION | D2: INS | E2: ISR | F2: Grand Total | G2: PHY | H2: DIF | I2: REMARKS
A3: 1 | B3: 1000015002 | C3: =VLOOKUP(B3,DATA!C:E,3,0) -> Bartec Feam Cable Gland; PAP-01 MON Bartec cable gland, armored cable type PAP-01-MON execution Ex d/e/I IIC, size 1 , male M20, in Nickel Plated Brass complete with kit of gaskets in EPDM + Accessories | D3: 192 | F3: 192 | G3: 192 | H3: =G3-F3 -> 0 | I3: Stock Matching
A4: 2 | B4: 1000015003 | C4: =VLOOKUP(B4,DATA!C:E,3,0) -> Bartec Feam Cable Gland; PAP-02 MON | D4: 231 | F4: 231 | G4: 231 | H4: =G4-F4 -> 0 | I4: Stock Matching
A5: 3 | B5: 1000015004 | C5: =VLOOKUP(B5,DATA!C:E,3,0) -> Bartec Feam Cable Gland; PAP-03-MON, male M32 in Nickel Plated Brass complete with kit of gaskets in EPDM with all accessories | D5: 1777 | F5: 1777 | G5: =233+1440+100+1 -> 1774 | H5: =G5-F5 -> -3 | I5: customer will Retun
A6: 4 | B6: 1000015005 | C6: =VLOOKUP(B6,DATA!C:E,3,0) -> Bartec Feam Cable Gland; PAP-04 MON | D6: 857 | F6: 857 | G6: 857 | H6: =G6-F6 -> 0 | I6: Stock Matching
A7: 5 | B7: 1000015006 | C7: =VLOOKUP(B7,DATA!C:E,3,0) -> Bartec Feam Cable Gland; PAP-05-MON, male M50 in Nickel Plated Brass complete with kit of gaskets in EPDM with all accessories | D7: 412 | F7: 412 | G7: 412 | H7: =G7-F7 -> 0 | I7: Stock Matching
A8: 6 | B8: 1000015007 | C8: =VLOOKUP(B8,DATA!C:E,3,0) -> Bartec Feam Cable Gland; PAP-06-MON, male M63 in Nickel Plated Brass complete with kit of gaskets in EPDM with all accessories | D8: 99 | F8: 99 | G8: 99 | H8: =G8-F8 -> 0 | I8: Stock Matching
A9: 7 | B9: 1000015008 | C9: =VLOOKUP(B9,DATA!C:E,3,0) -> Bartec Feam Cable Gland; PAP-07-MON, male M75 in Nickel Plated Brass complete with kit of gaskets in EPDM with all accessories | D9: 229 | F9: 229 | G9: 229 | H9: =G9-F9 -> 0 | I9: Stock Matching
A10: 8 | B10: 1000015009 | C10: =VLOOKUP(B10,DATA!C:E,3,0) -> Bartec Feam Cable Gland; PAP-08 MON | D10: 50 | F10: 50 | G10: 50 | H10: =G10-F10 -> 0 | I10: Stock Matching
A11: 9 | B11: 1000015011 | C11: =VLOOKUP(B11,DATA!C:E,3,0) -> Bartec Feam Cable Gland; PAP-01-NON, male 1/2" NPT in Nickel Plated Brass complete with kit of gaskets in EPDM with all accessories | D11: 4 | F11: 4 | G11: 4 | H11: =G11-F11 -> 0 | I11: Stock Matching
A12: 10 | B12: 1000015012 | C12: =VLOOKUP(B12,DATA!C:E,3,0) -> Bartec Feam Cable Gland; PAP-02-NON, male 3/4" NPT in Nickel Plated Brass complete with kit of gaskets in EPDM with all accessories | D12: 1821 | F12: 1821 | G12: 1821 | H12: =G12-F12 -> 0 | I12: Stock Matching
A13: 11 | B13: 1000015013 | C13: =VLOOKUP(B13,DATA!C:E,3,0) -> Bartec Feam Cable Gland; PAP-03-NON, male 1" NPT in Nickel Plated Brass complete with kit of gaskets in EPDM with all accessories | D13: 177 | F13: 177 | G13: 177 | H13: =G13-F13 -> 0 | I13: Stock Matching
A14: 12 | B14: 1000015014 | C14: =VLOOKUP(B14,DATA!C:E,3,0) -> Bartec Feam Cable Gland; PAP-04-NON, male 1 1 /4" NPT in Nickel Plated Brass complete with kit of gaskets in EPDM with all accessories | D14: 1220 | F14: 1220 | G14: 1220 | H14: =G14-F14 -> 0 | I14: Stock Matching
A15: 13 | B15: 1000015015 | C15: =VLOOKUP(B15,DATA!C:E,3,0) -> Bartec Feam Cable Gland; PAP-05-NON, male 1 1 /2" NPT in Nickel Plated Brass complete with kit of gaskets in EPDM with all accessories | D15: 164 | F15: 164 | G15: 164 | H15: =G15-F15 -> 0 | I15: Stock Matching
A16: 14 | B16: 1000015016 | C16: =VLOOKUP(B16,DATA!C:E,3,0) -> Bartec Feam Cable Gland; PAP-06-NON, male 2" NPT in Nickel Plated Brass complete with kit of gaskets in EPDM with all accessories | D16: 167 | F16: 167 | G16: 167 | H16: =G16-F16 -> 0 | I16: Stock Matching
A17: 15 | B17: 1000015017 | C17: =VLOOKUP(B17,DATA!C:E,3,0) -> Bartec Feam Cable Gland; PAP-07-NON, male 2 1/2" NPT in Nickel Plated Brass complete with kit of gaskets in EPDM with all accessories | D17: 30 | F17: 30 | G17: 30 | H17: =G17-F17 -> 0 | I17: Stock Matching
... A24: 22 | B24: 1000015029 | C24: =VLOOKUP(B24,DATA!C:E,3,0) -> Bartec Feam Cable Gland; PAP-R 01 NIX | D24: 2 | F24: 2 | G24: 0 | H24: =G24-F24 -> -2 | I24: Sample
A25: 23 | B25: 1000015030 | C25: =VLOOKUP(B25,DATA!C:E,3,0) -> Bartec Feam Cable Gland; PAP-R 02 NIX | E25: 1 | F25: 1 | G25: 0 | H25: =G25-F25 -> -1 | I25: ISR not Available
A26: 24 | B26: 1000015032 | C26: =VLOOKUP(B26,DATA!C:E,3,0) -> Bartec Feam Cable Gland; PAP-R 04 NIX | D26: 770 | F26: 770 | G26: 770 | H26: =G26-F26 -> 0 | I26: Stock Matching
A27: 25 | B27: 1000015034 | C27: =VLOOKUP(B27,DATA!C:E,3,0) -> Bartec Feam Cable Gland; PAP-R 06 NIX | D27: 271 | F27: 271 | G27: 51 | H27: =G27-F27 -> -220 | I27: Pending to close
A28: 26 | B28: 1000015038 | C28: =VLOOKUP(B28,DATA!C:E,3,0) -> Bartec Feam Cable Gland; PAP-R-01-NON, MALE 1/2" NPT in nickle plated brass complete with kit of gaskets in EPDM + FS0904 with all accessories | D28: 3205 | F28: 3205 | G28: 3205 | H28: =G28-F28 -> 0 | I28: Stock Matching | J28: Qty 325 found
A29: 27 | B29: 1000015039 | C29: =VLOOKUP(B29,DATA!C:E,3,0) -> Bartec Feam Cable Gland; PAP-R 02 NON,MALE 3/4 Inc NPT in Nickle plated brass complete with kit of gaskets in EPDM+FS0904 | D29: 1738 | F29: 1738 | G29: 1737 | H29: =G29-F29 -> -1 | I29: Sample
A30: 28 | B30: 1000015040 | C30: =VLOOKUP(B30,DATA!C:E,3,0) -> Bartec Feam Cable Gland; PAP-R-03-NON, MALE 1" NPT in nickle plated brass complete with kit of gaskets in EPDM + FS0904 with all accessories | D30: 2527 | F30: 2527 | G30: =1603+168+645-1 -> 2415 | H30: =G30-F30 -> -112 | I30: Pending to close
A31: 29 | B31: 1000015041 | C31: =VLOOKUP(B31,DATA!C:E,3,0) -> Bartec Feam Cable Gland; PAP-R-04-NON, MALE 1 1/4" NPT in nickle plated brass complete with kit of gaskets in EPDM + FS0904 with all accessories | D31: 835 | F31: 835 | G31: 833 | H31: =G31-F31 -> -2 | I31: MISSING
A32: 30 | B32: 1000015042 | C32: =VLOOKUP(B32,DATA!C:E,3,0) -> Bartec Feam Cable Gland; PAP-R 05 NON | D32: 36 | F32: 36 | G32: 36 | H32: =G32-F32 -> 0 | I32: Stock Matching
A33: 31 | B33: 1000015043 | C33: =VLOOKUP(B33,DATA!C:E,3,0) -> Bartec Feam Cable Gland; PAP-R 06 NON | D33: 152 | F33: 152 | G33: 148 | H33: =G33-F33 -> -4 | I33: RMA is Pending
A34: 32 | B34: 1000015045 | C34: =VLOOKUP(B34,DATA!C:E,3,0) -> Bartec Feam Cable Gland; PAP-R-08-NON, MALE 3" NPT in nickle plated brass complete with kit of gaskets in EPDM + FS0904 with all accessories | D34: 15 | F34: 15 | G34: 15 | H34: =G34-F34 -> 0 | I34: Stock Matching
A35: 33 | B35: 1000015047 | C35: =VLOOKUP(B35,DATA!C:E,3,0) -> Bartec Feam Cable Gland; PNA-01 MON | D35: 511 | F35: 511 | G35: 511 | H35: =G35-F35 -> 0 | I35: Stock Matching
A36: 34 | B36: 1000015048 | C36: =VLOOKUP(B36,DATA!C:E,3,0) -> Bartec Feam Cable Gland; PNA-02 MON | D36: 874 | F36: 874 | G36: 874 | H36: =G36-F36 -> 0 | I36: Stock Matching
A37: 35 | B37: 1000015049 | C37: =VLOOKUP(B37,DATA!C:E,3,0) -> Bartec Feam Cable Gland; PNA-03 MON | D37: 283 | F37: 283 | G37: 283 | H37: =G37-F37 -> 0 | I37: Stock Matching | L37: Remaining need to check in near warehouse
A38: 36 | B38: 1000015050 | C38: =VLOOKUP(B38,DATA!C:E,3,0) -> Bartec Feam Cable Gland; PNA-04 MON | D38: 242 | F38: 242 | G38: 242 | H38: =G38-F38 -> 0 | I38: Stock Matching
A39: 37 | B39: 1000015051 | C39: =VLOOKUP(B39,DATA!C:E,3,0) -> Bartec Feam Cable Gland; PNA-05 MON | D39: 408 | F39: 408 | G39: 408 | H39: =G39-F39 -> 0 | I39: Stock Matching
A40: 38 | B40: 1000015052 | C40: =VLOOKUP(B40,DATA!C:E,3,0) -> Bartec Feam Cable Gland; PNA-06 MON | D40: 175 | F40: 175 | G40: 175 | H40: =G40-F40 -> 0 | I40: Stock Matching
A41: 39 | B41: 1000015053 | C41: =VLOOKUP(B41,DATA!C:E,3,0) -> Bartec Feam Cable Gland; PNA-07 MON | D41: 40 | F41: 40 | G41: 40 | H41: =G41-F41 -> 0 | I41: Stock Matching
A42: 40 | B42: 1000015056 | C42: =VLOOKUP(B42,DATA!C:E,3,0) -> Bartec Feam Cable Gland; PNA-01 NON | D42: 633 | F42: 633 | G42: 633 | H42: =G42-F42 -> 0 | I42: Stock Matching
A43: 41 | B43: 1000015057 | C43: =VLOOKUP(B43,DATA!C:E,3,0) -> Bartec Feam Cable Gland;PNA-02 NON, MALE 3/4" NPT in nickle plated brass complete with kit of gaskets in EPDM | D43: 391 | F43: 391 | G43: =384+6+1 -> 391 | H43: =G43-F43 -> 0 | I43: Stock Matching
A44: 42 | B44: 1000015058 | C44: =VLOOKUP(B44,DATA!C:E,3,0) -> Bartec Feam Cable Gland; PNA-03 NON, male 1" NPT in nickle plated brass complete with kit of gaskets in EPDM | D44: 87 | F44: 87 | G44: 87 | H44: =G44-F44 -> 0 | I44: Stock Matching
A45: 43 | B45: 1000015059 | C45: =VLOOKUP(B45,DATA!C:E,3,0) -> Bartec Feam Cable Gland; PNA-04 NON | D45: 389 | F45: 389 | G45: 388 | H45: =G45-F45 -> -1 | I45: MISSING
A46: 44 | B46: 1000015060 | C46: =VLOOKUP(B46,DATA!C:E,3,0) -> Bartec Feam Cable Gland; PNA-05 NON | D46: 139 | F46: 139 | G46: 139 | H46: =G46-F46 -> 0 | I46: Stock Matching
A47: 45 | B47: 1000015061 | C47: =VLOOKUP(B47,DATA!C:E,3,0) -> Bartec Feam Cable Gland; PNA-06 NON | D47: 32 | F47: 32 | G47: 32 | H47: =G47-F47 -> 0 | I47: Stock Matching
...

Sheet DATA
A1: No | B1: UNIT | C1: Item Code | D1: Supplier Name | E1: Description | F1: ERP
A2: 1 | B2: INS | C2: 1000093076 | D2: Bartec Middle East LLC | E2: 3-SS Cable Glands Including Accessories (PAP-R-05-MIX) | F2: 885
A3: 2 | B3: INS | C3: 1000097213 | D3: Bartec Middle East LLC | E3: 3-SS Cable Glands Including Accessories (PNA-R-01-MIX) | F3: 512
A4: 3 | B4: INS | C4: 1000103589 | D4: Bartec Middle East LLC | E4: Barrier cable gland, Unarmored cable type PNA-R-01-NXX execution Ex d/e/I IIC, size 1 , male 1/2" NPT, in stainless steel complete with kit of gaskets in EPDM + Accessories + FS0904-1 | F4: 983
A5: 4 | B5: INS | C5: 1000104330 | D5: Bartec Middle East LLC | E5: Ammeeter AM72 , X/1A, 0-20 A with fixing kit EXE | F5: 2
A6: 5 | B6: INS | C6: 1000106261 | D6: Bartec Middle East LLC | E6: Reducre female-male type REB05N05MXX, execution Ex d/e IIC, female 1-1/2" NPT, male M50x1.5, in stainless steel AISI316L | F6: 257
A7: 6 | B7: INS | C7: 1000108220 | D7: Bartec Middle East LLC | E7: Seal compound part number - INN-FS0904-2 | F7: 20
A8: 7 | B8: INS | C8: 1000093085 | D8: Bartec Middle East LLC | E8: 3-SS Cable Glands Including Accessories (PNA-R-02-NIX) | F8: 128
A9: 8 | B9: INS | C9: 1000094250 | D9: Bartec Middle East LLC | E9: 3-SS Cable Glands Including Accessories (PAP-R-04-MIX) | F9: 118
A10: 9 | B10: INS | C10: 1000106265 | D10: Bartec Middle East LLC | E10: HEXAGONAL HEAD COLLAR; PLG-04-NXX | F10: 135
A11: 10 | B11: INS | C11: 1000099598 | D11: Bartec Middle East LLC | E11: 3-SS Cable Glands Including Accessories (PAP-R-06-MIX) | F11: 200
A12: 11 | B12: INS | C12: 1000102156 | D12: Bartec Middle East LLC | E12: Yellow Lamp Module Actuator: 05-0003-001500 | F12: 50
A13: 12 | B13: INS | C13: 1000103261 | D13: Bartec Middle East LLC | E13: Selector switch 3 position PN:05-0003-001000 | F13: 65
... A87: 86 | B87: INS | C87: 1000091161 | D87: Bartec Middle East LLC | E87: Bartec Feam Cable Gland; PAP-02 NIX | F87: 559
A88: 87 | B88: INS | C88: 1000092295 | E88: Bartec, Feam SS Junction Box ESX 4433 size 330 X 440 X 200mm | F88: 1
A89: 88 | B89: INS | C89: 1000093326 | D89: Bartec Middle East LLC | E89: Bartec Feam Cable Gland; PAP-R-01-MON | F89: 319
A90: 89 | B90: INS | C90: 1000099208 | D90: JAWDAT TAYIBA TRADING EST | E90: Bartec M50 SS316 locknut & IP washer | F90: 179
A91: 90 | B91: INS | C91: 1000099441 | D91: Bartec Middle East LLC | E91: Bartec Feam Cable Gland; PAP-R 04 MON + KIT | F91: 450
A92: 91 | B92: INS | C92: 1000101038 | D92: Bartec Middle East LLC | E92: Bartec Feam Cable Gland; PNA-R-02-MIX + KIT | F92: 765
A93: 92 | B93: INS | C93: 1000101321 | D93: Bartec Middle East LLC | E93: Bartec, Feam Plugs PLG-06-MON | F93: 86
A94: 93 | B94: INS | C94: 1000102394 | D94: Bartec Middle East LLC | E94: Bartec Feam Cable Gland; PAP-R01-MXX , male M20 in Stainless steel complete with Kit of gaskets in EPDDM + FS0904 | F94: 8
A95: 94 | B95: INS | C95: 1000102397 | D95: Bartec Middle East LLC | E95: Bartec Feam Cable Gland; PAP-01-MXX + Kit | F95: 1637
A96: 95 | B96: INS | C96: 1000102686 | D96: Bartec Middle East LLC | E96: Bartec, Feam Plugs PLG-07-NON | F96: 160
A97: 96 | B97: INS | C97: 1000103355 | D97: Bartec Middle East LLC | E97: Bartec Product; RE-02N01MXX | F97: 176
A98: 97 | B98: INS | C98: 1000103510 | D98: Bartec Middle East LLC | E98: Bartec Product; SS316L PAP-R-06-NXX+kit accessories | F98: 224
A99: 98 | B99: INS | C99: 1000105610 | D99: Bartec Middle East LLC | E99: Reducer female-male type REB02N02MXX, execution Ex d/e IIC, female 3/4"NPT, male M25x1.5, in stainless steel AISI316L, BARTEC FN, IECEx certificate | F99: 2079
A100: 99 | B100: INS | C100: 1000105611 | D100: Bartec Middle East LLC | E100: Reducer female-male type REB03N03MXX, execution Ex d/e IIC, female 1"NPT, male M32x1.5, in stainless steel AISI316L, BARTEC FN, IECEx certificate | F100: 27
... A186: 185 | B186: INS | C186: 1000015114 | D186: Bartec Middle East LLC | E186: Bartec, Feam Lightining Fixture EVAC301-250HPNA-SM | F186: 7
A187: 186 | B187: INS | C187: 1000015122 | E187: Bartec, Feam SS Junction Box ESX 3333 size 330 X 330 X 148 | F187: 3
A188: 187 | B188: INS | C188: 1000015123 | D188: Bartec Middle East LLC | E188: Bartec, Feam SS Junction Box ESX 3333 size 330 X 330 X 200 | F188: 4
A189: 188 | B189: INS | C189: 1000101324 | D189: Bartec Middle East LLC | E189: Bartec, Feam Plugs; Reducers; REB-02N-02-MIX | F189: 134
A190: 189 | B190: INS | C190: 1000101328 | D190: Bartec Middle East LLC | E190: Bartec, Feam Plugs; Reducers; RE-04N-01-MIX | F190: 200
A191: 190 | B191: INS | C191: 1000103354 | D191: Bartec Middle East LLC | E191: Bartec Product; REB-04N03MXX | F191: 100
A192: 191 | B192: INS | C192: 1000103505 | D192: Bartec Middle East LLC | E192: Bartec Product; SS316L PAP-02-NXX+kit accessories | F192: 40
A193: 192 | B193: INS | C193: 1000103507 | D193: Bartec Middle East LLC | E193: Bartec Product; SS316L PAP-06-NXX+kit accessories | F193: 100
A194: 193 | B194: INS | C194: 1000103517 | D194: Bartec Middle East LLC | E194: Bartec Product; SS316L 3/4" MALE TO 1/2" FEMALE TYPE RE#02N01NXX | F194: 30
A195: 194 | B195: INS | C195: 1000103588 | D195: Bartec Middle East LLC | E195: Bartec Product; SS316L PNA-R-01-MXX+kit accessories | F195: 78
A196: 195 | B196: INS | C196: 1000103592 | D196: Bartec Middle East LLC | E196: Bartec Product; SS316L PNA-R-04-NXX+kit accessories | F196: 295
A197: 196 | B197: INS | C197: 1000103629 | D197: Bartec Middle East LLC | E197: Bartec Feam Cable Gland; PAP-R-06-MON | F197: 100
A198: 197 | B198: INS | C198: 1000104001 | D198: Bartec Middle East LLC | E198: Bartec Product; PLG-01-MXX | F198: 2490
...
